<?xml version="1.0"?>
<!--
\author   Raffaello Bonghi <raffaello@rnext.it
\copyright Copyright (c) 2016, Raffaello Bonghi All rights reserved.
Redistribution and use in source and binary forms, with or without
modification, are permitted provided that the following conditions are met:
    * Redistributions of source code must retain the above copyright
      notice, this list of conditions and the following disclaimer.
    * Redistributions in binary form must reproduce the above copyright
      notice, this list of conditions and the following disclaimer in the
      documentation and/or other materials provided with the distribution.
    * Neither the name of Officine Robotiche nor the
      names of its contributors may be used to endorse or promote products
      derived from this software without specific prior written permission.
THIS SOFTWARE IS PROVIDED BY THE COPYRIGHT HOLDERS AND CONTRIBUTORS "AS IS" AND
ANY EXPRESS OR IMPLIED WARRANTIES, INCLUDING, BUT NOT LIMITED TO, THE IMPLIED
WARRANTIES OF MERCHANTABILITY AND FITNESS FOR A PARTICULAR PURPOSE ARE
DISCLAIMED. IN NO EVENT SHALL THE COPYRIGHT HOLDERS BE LIABLE FOR ANY
DIRECT, INDIRECT, INCIDENTAL, SPECIAL, EXEMPLARY, OR CONSEQUENTIAL DAMAGES
(INCLUDING, BUT NOT LIMITED TO, PROCUREMENT OF SUBSTITUTE GOODS OR SERVICES;
LOSS OF USE, DATA, OR PROFITS; OR BUSINESS INTERRUPTION) HOWEVER CAUSED AND
ON ANY THEORY OF LIABILITY, WHETHER IN CONTRACT, STRICT LIABILITY, OR TORT
(INCLUDING NEGLIGENCE OR OTHERWISE) ARISING IN ANY WAY OUT OF THE USE OF THIS
SOFTWARE, EVEN IF ADVISED OF THE POSSIBILITY OF SUCH DAMAGE.
-->
<robot name="example">
	<!-- Base link position -->
	<link name="base_link">
		<visual>
			<origin rpy="0.0 0.0 0.0" xyz="0.0 0.0 0.06" />
			<geometry>
				<cylinder length="0.1" radius="0.1" />
			</geometry>
			<material name="green">
				<color rgba="0 1 0 0.5"/>
			</material>
		</visual>
	</link>
	<!-- Left wheel link -->
	<link name="left_wheel">
		<visual>
			<geometry>
				<cylinder length="0.02" radius="0.05"/>
			</geometry>
			<material name="black">
				<color rgba="0 0 0 1"/>
			</material>
		</visual>
    <collision>
      <geometry>
        <cylinder length="0.02" radius="0.05"/>
      </geometry>
    </collision>
	</link>
	<!-- Joint configuration left joint -->
	<joint name="left_joint" type="continuous">
		<axis xyz="0 0 -1"/>
		<parent link="base_link"/>
		<child link="left_wheel"/>
		<origin rpy="1.57075 0.0 0.0" xyz="0 0.1 0.05"/>
		<limit effort="2" velocity="10"/>
		<joint_properties damping="0.02" friction="0.04"/>
	</joint>
	<!-- Transmission configuration left joint -->
	<transmission name="$left_trans" type="SimpleTransmission">
		<type>transmission_interface/SimpleTransmission</type>
		<actuator name="$left_motor">
			<mechanicalReduction>1</mechanicalReduction>
		</actuator>
		<joint name="left_joint">
			<hardwareInterface>VelocityJointInterface</hardwareInterface>
		</joint>
	</transmission>

	<!-- Right wheel link -->
	<link name="right_wheel">
		<visual>
			<geometry>
				<cylinder length="0.02" radius="0.05"/>
			</geometry>
			<material name="black">
				<color rgba="0 0 0 1"/>
			</material>
		</visual>
    <collision>
      <geometry>
        <cylinder length="0.02" radius="0.05"/>
      </geometry>
    </collision>
	</link>
	<!-- Joint configuration left joint -->
	<joint name="right_joint" type="continuous">
		<axis xyz="0 0 -1"/>
		<parent link="base_link"/>
		<child link="right_wheel"/>
		<origin rpy="1.57075 0.0 0.0" xyz="0 -0.1 0.05"/>
		<limit effort="2" velocity="10"/>
		<joint_properties damping="0.02" friction="0.04"/>
	</joint>
	<!-- Transmission configuration right joint -->
	<transmission name="$right_trans" type="SimpleTransmission">
		<type>transmission_interface/SimpleTransmission</type>
		<actuator name="$right_motor">
			<mechanicalReduction>1</mechanicalReduction>
		</actuator>
		<joint name="right_joint">
			<hardwareInterface>VelocityJointInterface</hardwareInterface>
		</joint>
	</transmission>
	
</robot>
